2021-03-29 19:23:48,812 dellemc_powerstore_gatherfacts.py INFO : HAS_PY4PS = True, IMPORT_ERROR = 
2021-03-29 19:23:48,813 dellemc_powerstore_gatherfacts.py INFO : IS_SUPPORTED_PY4PS_VERSION = True , VERSION_ERROR = 
2021-03-29 19:23:48,813 dellemc_powerstore_gatherfacts.py INFO : Got Py4ps instance for provisioning on PowerStore <PyPowerStore.powerstore_conn.PowerStoreConn object at 0x7f92e67b43d0>
2021-03-29 19:23:53,822 dellemc_powerstore_gatherfacts.py ERROR : Failed to get the clusters with error HTTPSConnectionPool(host='ip_address_of_the_array', port=443): Max retries exceeded with url: /api/rest/cluster?select=id%2Cname (Caused by NewConnectionError('<urllib3.connection.HTTPSConnection object at 0x7f92e66ee280>: Failed to establish a new connection: [Errno -3] Try again'))
2021-03-29 19:26:07,632 dellemc_powerstore_gatherfacts.py INFO : HAS_PY4PS = True, IMPORT_ERROR = 
2021-03-29 19:26:07,633 dellemc_powerstore_gatherfacts.py INFO : IS_SUPPORTED_PY4PS_VERSION = True , VERSION_ERROR = 
2021-03-29 19:26:07,633 dellemc_powerstore_gatherfacts.py INFO : Got Py4ps instance for provisioning on PowerStore <PyPowerStore.powerstore_conn.PowerStoreConn object at 0x7f207dac03d0>
2021-03-29 19:26:07,704 dellemc_powerstore_gatherfacts.py INFO : Getting vol list
2021-03-29 19:26:07,781 dellemc_powerstore_gatherfacts.py INFO : Successfully listed 0 Volumes from powerstore array name: POD3-Cluster1 , global id : 0
2021-03-29 19:26:08,507 dellemc_powerstore_gatherfacts.py INFO : HAS_PY4PS = True, IMPORT_ERROR = 
2021-03-29 19:26:08,508 dellemc_powerstore_gatherfacts.py INFO : IS_SUPPORTED_PY4PS_VERSION = True , VERSION_ERROR = 
2021-03-29 19:26:08,508 dellemc_powerstore_gatherfacts.py INFO : Got Py4ps instance for provisioning on PowerStore <PyPowerStore.powerstore_conn.PowerStoreConn object at 0x7f250d8d33d0>
2021-03-29 19:26:08,597 dellemc_powerstore_gatherfacts.py INFO : Getting vol list
2021-03-29 19:26:08,664 dellemc_powerstore_gatherfacts.py INFO : Successfully listed 0 Volumes from powerstore array name: POD3-Cluster1 , global id : 0
2021-03-29 20:23:14,532 dellemc_powerstore_gatherfacts.py INFO : HAS_PY4PS = True, IMPORT_ERROR = 
2021-03-29 20:23:14,532 dellemc_powerstore_gatherfacts.py INFO : IS_SUPPORTED_PY4PS_VERSION = True , VERSION_ERROR = 
2021-03-29 20:23:14,532 dellemc_powerstore_gatherfacts.py INFO : Got Py4ps instance for provisioning on PowerStore <PyPowerStore.powerstore_conn.PowerStoreConn object at 0x7fdceedd33d0>
2021-03-29 20:23:14,605 dellemc_powerstore_gatherfacts.py INFO : Getting vol list
2021-03-29 20:23:14,665 dellemc_powerstore_gatherfacts.py INFO : Successfully listed 0 Volumes from powerstore array name: POD3-Cluster1 , global id : 0
2021-03-29 20:23:15,321 dellemc_powerstore_gatherfacts.py INFO : HAS_PY4PS = True, IMPORT_ERROR = 
2021-03-29 20:23:15,321 dellemc_powerstore_gatherfacts.py INFO : IS_SUPPORTED_PY4PS_VERSION = True , VERSION_ERROR = 
2021-03-29 20:23:15,321 dellemc_powerstore_gatherfacts.py INFO : Got Py4ps instance for provisioning on PowerStore <PyPowerStore.powerstore_conn.PowerStoreConn object at 0x7fa9956c53d0>
2021-03-29 20:23:15,385 dellemc_powerstore_gatherfacts.py INFO : Getting vol list
2021-03-29 20:23:15,439 dellemc_powerstore_gatherfacts.py INFO : Successfully listed 0 Volumes from powerstore array name: POD3-Cluster1 , global id : 0
